Workbook

Sheet Summary
A2: Results for Tables 2 and 3
A3: Acc and w-F1 are percentage values. SD is the sample standard deviation (ddof = 1).
A5: Group ID | B5: Dataset | C5: Model | D5: IMR (A, L, V) | E5: Seeds | F5: Acc | G5: Acc SD | H5: w-F1 | I5: w-F1 SD
A6: G01 | B6: IEMOCAP | C6: GCNet+AMBER | D6: (0.3,0.5,0.7) | E6: 5 | F6: =AVERAGE(Runs!G6:G10) -> 61.848429 | G6: =STDEV(Runs!G6:G10) -> 1.0322923 | H6: =AVERAGE(Runs!H6:H10) -> 61.684232 | I6: =STDEV(Runs!H6:H10) -> 1.0838387
A7: G02 | B7: IEMOCAP | C7: GCNet+AMBER | D7: (0.3,0.7,0.5) | E7: 5 | F7: =AVERAGE(Runs!G11:G15) -> 59.926063 | G7: =STDEV(Runs!G11:G15) -> 0.68831744 | H7: =AVERAGE(Runs!H11:H15) -> 59.200087 | I7: =STDEV(Runs!H11:H15) -> 0.49601531
A8: G03 | B8: IEMOCAP | C8: GCNet+AMBER | D8: (0.5,0.3,0.7) | E8: 5 | F8: =AVERAGE(Runs!G16:G20) -> 65.163278 | G8: =STDEV(Runs!G16:G20) -> 1.4610515 | H8: =AVERAGE(Runs!H16:H20) -> 64.681077 | I8: =STDEV(Runs!H16:H20) -> 1.6684784
A9: G04 | B9: IEMOCAP | C9: GCNet+AMBER | D9: (0.5,0.7,0.3) | E9: 5 | F9: =AVERAGE(Runs!G21:G25) -> 60.579174 | G9: =STDEV(Runs!G21:G25) -> 0.94993977 | H9: =AVERAGE(Runs!H21:H25) -> 60.216233 | I9: =STDEV(Runs!H21:H25) -> 0.91695789
A10: G05 | B10: IEMOCAP | C10: GCNet+AMBER | D10: (0.7,0.3,0.5) | E10: 5 | F10: =AVERAGE(Runs!G26:G30) -> 65.348121 | G10: =STDEV(Runs!G26:G30) -> 0.92380356 | H10: =AVERAGE(Runs!H26:H30) -> 64.899425 | I10: =STDEV(Runs!H26:H30) -> 0.81047456
A11: G06 | B11: IEMOCAP | C11: GCNet+AMBER | D11: (0.7,0.5,0.3) | E11: 5 | F11: =AVERAGE(Runs!G31:G35) -> 62.378312 | G11: =STDEV(Runs!G31:G35) -> 0.47646617 | H11: =AVERAGE(Runs!H31:H35) -> 61.865266 | I11: =STDEV(Runs!H31:H35) -> 0.34644191
A12: G07 | B12: IEMOCAP | C12: MMGCN+AMBER | D12: (0.3,0.5,0.7) | E12: 5 | F12: =AVERAGE(Runs!G36:G40) -> 64.645718 | G12: =STDEV(Runs!G36:G40) -> 1.3310684 | H12: =AVERAGE(Runs!H36:H40) -> 64.50419 | I12: =STDEV(Runs!H36:H40) -> 1.2419422
A13: G08 | B13: IEMOCAP | C13: MMGCN+AMBER | D13: (0.3,0.7,0.5) | E13: 5 | F13: =AVERAGE(Runs!G41:G45) -> 63.080715 | G13: =STDEV(Runs!G41:G45) -> 0.60432285 | H13: =AVERAGE(Runs!H41:H45) -> 62.731403 | I13: =STDEV(Runs!H41:H45) -> 0.49228199
A14: G09 | B14: IEMOCAP | C14: MMGCN+AMBER | D14: (0.5,0.3,0.7) | E14: 5 | F14: =AVERAGE(Runs!G46:G50) -> 65.409735 | G14: =STDEV(Runs!G46:G50) -> 0.51660564 | H14: =AVERAGE(Runs!H46:H50) -> 65.250474 | I14: =STDEV(Runs!H46:H50) -> 0.49744602
A15: G10 | B15: IEMOCAP | C15: MMGCN+AMBER | D15: (0.5,0.7,0.3) | E15: 5 | F15: =AVERAGE(Runs!G51:G55) -> 62.982132 | G15: =STDEV(Runs!G51:G55) -> 0.78470588 | H15: =AVERAGE(Runs!H51:H55) -> 62.682262 | I15: =STDEV(Runs!H51:H55) -> 0.87958641
A16: G11 | B16: IEMOCAP | C16: MMGCN+AMBER | D16: (0.7,0.3,0.5) | E16: 5 | F16: =AVERAGE(Runs!G56:G60) -> 64.054221 | G16: =STDEV(Runs!G56:G60) -> 1.6117762 | H16: =AVERAGE(Runs!H56:H60) -> 63.885269 | I16: =STDEV(Runs!H56:H60) -> 1.5065711
A17: G12 | B17: IEMOCAP | C17: MMGCN+AMBER | D17: (0.7,0.5,0.3) | E17: 5 | F17: =AVERAGE(Runs!G61:G65) -> 63.130006 | G17: =STDEV(Runs!G61:G65) -> 0.81111188 | H17: =AVERAGE(Runs!H61:H65) -> 62.804348 | I17: =STDEV(Runs!H61:H65) -> 0.73890148
A18: G13 | B18: IEMOCAP | C18: MM-DFN+AMBER | D18: (0.3,0.5,0.7) | E18: 5 | F18: =AVERAGE(Runs!G66:G70) -> 67.430684 | G18: =STDEV(Runs!G66:G70) -> 0.71270456 | H18: =AVERAGE(Runs!H66:H70) -> 67.023426 | I18: =STDEV(Runs!H66:H70) -> 0.56456084
A19: G14 | B19: IEMOCAP | C19: MM-DFN+AMBER | D19: (0.3,0.7,0.5) | E19: 5 | F19: =AVERAGE(Runs!G71:G75) -> 65.003081 | G19: =STDEV(Runs!G71:G75) -> 0.90658897 | H19: =AVERAGE(Runs!H71:H75) -> 64.414154 | I19: =STDEV(Runs!H71:H75) -> 1.0144428
A20: G15 | B20: IEMOCAP | C20: MM-DFN+AMBER | D20: (0.5,0.3,0.7) | E20: 5 | F20: =AVERAGE(Runs!G76:G80) -> 68.428835 | G20: =STDEV(Runs!G76:G80) -> 0.71270456 | H20: =AVERAGE(Runs!H76:H80) -> 68.116416 | I20: =STDEV(Runs!H76:H80) -> 0.8149771
A21: G16 | B21: IEMOCAP | C21: MM-DFN+AMBER | D21: (0.5,0.7,0.3) | E21: 5 | F21: =AVERAGE(Runs!G81:G85) -> 64.658041 | G21: =STDEV(Runs!G81:G85) -> 0.74906361 | H21: =AVERAGE(Runs!H81:H85) -> 64.063402 | I21: =STDEV(Runs!H81:H85) -> 0.61463649
A22: G17 | B22: IEMOCAP | C22: MM-DFN+AMBER | D22: (0.7,0.3,0.5) | E22: 5 | F22: =AVERAGE(Runs!G86:G90) -> 67.652495 | G22: =STDEV(Runs!G86:G90) -> 0.67635547 | H22: =AVERAGE(Runs!H86:H90) -> 67.406084 | I22: =STDEV(Runs!H86:H90) -> 0.669355
A23: G18 | B23: IEMOCAP | C23: MM-DFN+AMBER | D23: (0.7,0.5,0.3) | E23: 5 | F23: =AVERAGE(Runs!G91:G95) -> 66.494147 | G23: =STDEV(Runs!G91:G95) -> 0.63195965 | H23: =AVERAGE(Runs!H91:H95) -> 65.940851 | I23: =STDEV(Runs!H91:H95) -> 0.25417273
A24: G19 | B24: CMU-MOSEI | C24: GCNet+AMBER | D24: (0.3,0.5,0.7) | E24: 5 | F24: =AVERAGE(Runs!G96:G100) -> 81.766648 | G24: =STDEV(Runs!G96:G100) -> 0.29226017 | H24: =AVERAGE(Runs!H96:H100) -> 81.596495 | I24: =STDEV(Runs!H96:H100) -> 0.24860673
A25: G20 | B25: CMU-MOSEI | C25: GCNet+AMBER | D25: (0.3,0.7,0.5) | E25: 5 | F25: =AVERAGE(Runs!G101:G105) -> 79.592735 | G25: =STDEV(Runs!G101:G105) -> 0.64317725 | H25: =AVERAGE(Runs!H101:H105) -> 79.394907 | I25: =STDEV(Runs!H101:H105) -> 0.68861721
A26: G21 | B26: CMU-MOSEI | C26: GCNet+AMBER | D26: (0.5,0.3,0.7) | E26: 5 | F26: =AVERAGE(Runs!G106:G110) -> 84.177215 | G26: =STDEV(Runs!G106:G110) -> 0.57227943 | H26: =AVERAGE(Runs!H106:H110) -> 83.960181 | I26: =STDEV(Runs!H106:H110) -> 0.5433317
A27: G22 | B27: CMU-MOSEI | C27: GCNet+AMBER | D27: (0.5,0.7,0.3) | E27: 5 | F27: =AVERAGE(Runs!G111:G115) -> 78.915795 | G27: =STDEV(Runs!G111:G115) -> 0.34446855 | H27: =AVERAGE(Runs!H111:H115) -> 78.606349 | I27: =STDEV(Runs!H111:H115) -> 0.43461812
A28: G23 | B28: CMU-MOSEI | C28: GCNet+AMBER | D28: (0.7,0.3,0.5) | E28: 5 | F28: =AVERAGE(Runs!G116:G120) -> 84.072647 | G28: =STDEV(Runs!G116:G120) -> 0.29406824 | H28: =AVERAGE(Runs!H116:H120) -> 83.923446 | I28: =STDEV(Runs!H116:H120) -> 0.3479317
A29: G24 | B29: CMU-MOSEI | C29: GCNet+AMBER | D29: (0.7,0.5,0.3) | E29: 5 | F29: =AVERAGE(Runs!G121:G125) -> 82.305999 | G29: =STDEV(Runs!G121:G125) -> 0.23671781 | H29: =AVERAGE(Runs!H121:H125) -> 82.157709 | I29: =STDEV(Runs!H121:H125) -> 0.28373981
A30: G25 | B30: CMU-MOSEI | C30: MMGCN+AMBER | D30: (0.3,0.5,0.7) | E30: 5 | F30: =AVERAGE(Runs!G126:G130) -> 82.718767 | G30: =STDEV(Runs!G126:G130) -> 0.14946038 | H30: =AVERAGE(Runs!H126:H130) -> 82.586945 | I30: =STDEV(Runs!H126:H130) -> 0.12522175
A31: G26 | B31: CMU-MOSEI | C31: MMGCN+AMBER | D31: (0.3,0.7,0.5) | E31: 5 | F31: =AVERAGE(Runs!G131:G135) -> 80.209136 | G31: =STDEV(Runs!G131:G135) -> 0.23543478 | H31: =AVERAGE(Runs!H131:H135) -> 79.770512 | I31: =STDEV(Runs!H131:H135) -> 0.23996651
A32: G27 | B32: CMU-MOSEI | C32: MMGCN+AMBER | D32: (0.5,0.3,0.7) | E32: 5 | F32: =AVERAGE(Runs!G136:G140) -> 85.008255 | G32: =STDEV(Runs!G136:G140) -> 0.20902729 | H32: =AVERAGE(Runs!H136:H140) -> 84.872985 | I32: =STDEV(Runs!H136:H140) -> 0.19032892
A33: G28 | B33: CMU-MOSEI | C33: MMGCN+AMBER | D33: (0.5,0.7,0.3) | E33: 5 | F33: =AVERAGE(Runs!G141:G145) -> 80.203632 | G33: =STDEV(Runs!G141:G145) -> 0.55228063 | H33: =AVERAGE(Runs!H141:H145) -> 79.953258 | I33: =STDEV(Runs!H141:H145) -> 0.49388147
A34: G29 | B34: CMU-MOSEI | C34: MMGCN+AMBER | D34: (0.7,0.3,0.5) | E34: 5 | F34: =AVERAGE(Runs!G146:G150) -> 84.865162 | G34: =STDEV(Runs!G146:G150) -> 0.15444376 | H34: =AVERAGE(Runs!H146:H150) -> 84.742777 | I34: =STDEV(Runs!H146:H150) -> 0.14796906
A35: G30 | B35: CMU-MOSEI | C35: MMGCN+AMBER | D35: (0.7,0.5,0.3) | E35: 5 | F35: =AVERAGE(Runs!G151:G155) -> 82.977435 | G35: =STDEV(Runs!G151:G155) -> 0.30679667 | H35: =AVERAGE(Runs!H151:H155) -> 82.803098 | I35: =STDEV(Runs!H151:H155) -> 0.23833668
A36: G31 | B36: CMU-MOSEI | C36: MM-DFN+AMBER | D36: (0.3,0.5,0.7) | E36: 5 | F36: =AVERAGE(Runs!G156:G160) -> 82.751789 | G36: =STDEV(Runs!G156:G160) -> 0.21876287 | H36: =AVERAGE(Runs!H156:H160) -> 82.719356 | I36: =STDEV(Runs!H156:H160) -> 0.17219752
A37: G32 | B37: CMU-MOSEI | C37: MM-DFN+AMBER | D37: (0.3,0.7,0.5) | E37: 5 | F37: =AVERAGE(Runs!G161:G165) -> 79.823886 | G37: =STDEV(Runs!G161:G165) -> 0.20811965 | H37: =AVERAGE(Runs!H161:H165) -> 79.491516 | I37: =STDEV(Runs!H161:H165) -> 0.19935037
A38: G33 | B38: CMU-MOSEI | C38: MM-DFN+AMBER | D38: (0.5,0.3,0.7) | E38: 5 | F38: =AVERAGE(Runs!G166:G170) -> 84.810127 | G38: =STDEV(Runs!G166:G170) -> 0.07015712 | H38: =AVERAGE(Runs!H166:H170) -> 84.72467 | I38: =STDEV(Runs!H166:H170) -> 0.13883706
A39: G34 | B39: CMU-MOSEI | C39: MM-DFN+AMBER | D39: (0.5,0.7,0.3) | E39: 5 | F39: =AVERAGE(Runs!G171:G175) -> 79.823886 | G39: =STDEV(Runs!G171:G175) -> 0.23301005 | H39: =AVERAGE(Runs!H171:H175) -> 79.553056 | I39: =STDEV(Runs!H171:H175) -> 0.051042724
A40: G35 | B40: CMU-MOSEI | C40: MM-DFN+AMBER | D40: (0.7,0.3,0.5) | E40: 5 | F40: =AVERAGE(Runs!G176:G180) -> 84.964227 | G40: =STDEV(Runs!G176:G180) -> 0.28637118 | H40: =AVERAGE(Runs!H176:H180) -> 84.849902 | I40: =STDEV(Runs!H176:H180) -> 0.27073832
A41: G36 | B41: CMU-MOSEI | C41: MM-DFN+AMBER | D41: (0.7,0.5,0.3) | E41: 5 | F41: =AVERAGE(Runs!G181:G185) -> 82.856357 | G41: =STDEV(Runs!G181:G185) -> 0.66585325 | H41: =AVERAGE(Runs!H181:H185) -> 82.67979 | I41: =STDEV(Runs!H181:H185) -> 0.59948527

Sheet Runs
A2: Runs used in Tables 2 and 3
A3: Metrics come from final log excerpts. Numeric seeds are represented by aliases within each condition.
A5: Run ID | B5: Group ID | C5: Dataset | D5: Model | E5: IMR (A, L, V) | F5: Seed alias | G5: Acc | H5: w-F1 | I5: Selected epoch | J5: Included | K5: Log match | L5: Exit code
A6: G01-seed1 | B6: G01 | C6: IEMOCAP | D6: GCNet+AMBER | E6: (0.3,0.5,0.7) | F6: seed1 | G6: 62.908195 | H6: 62.900252 | I6: 124 | J6: Yes | K6: Match | L6: 3221226505
A7: G01-seed2 | B7: G01 | C7: IEMOCAP | D7: GCNet+AMBER | E7: (0.3,0.5,0.7) | F7: seed2 | G7: 61.55268 | H7: 61.729087 | I7: 139 | J7: Yes | K7: Match | L7: 3221226505
A8: G01-seed3 | B8: G01 | C8: IEMOCAP | D8: GCNet+AMBER | E8: (0.3,0.5,0.7) | F8: seed3 | G8: 60.813309 | H8: 60.4728 | I8: 27 | J8: Yes | K8: Match | L8: 3221226505
A9: G01-seed4 | B9: G01 | C9: IEMOCAP | D9: GCNet+AMBER | E9: (0.3,0.5,0.7) | F9: seed4 | G9: 60.998152 | H9: 60.724279 | I9: 75 | J9: Yes | K9: Match | L9: 3221226505
A10: G01-seed5 | B10: G01 | C10: IEMOCAP | D10: GCNet+AMBER | E10: (0.3,0.5,0.7) | F10: seed5 | G10: 62.969809 | H10: 62.594743 | I10: 36 | J10: Yes | K10: Match | L10: 3221226505
A11: G02-seed1 | B11: G02 | C11: IEMOCAP | D11: GCNet+AMBER | E11: (0.3,0.7,0.5) | F11: seed1 | G11: 60.69008 | H11: 59.690165 | I11: 149 | J11: Yes | K11: Match | L11: 3221226505
A12: G02-seed2 | B12: G02 | C12: IEMOCAP | D12: GCNet+AMBER | E12: (0.3,0.7,0.5) | F12: seed2 | G12: 59.581023 | H12: 59.09599 | I12: 57 | J12: Yes | K12: Match | L12: 3221226505
A13: G02-seed3 | B13: G02 | C13: IEMOCAP | D13: GCNet+AMBER | E13: (0.3,0.7,0.5) | F13: seed3 | G13: 58.96488 | H13: 58.635035 | I13: 46 | J13: Yes | K13: Match | L13: 3221226505
A14: G02-seed4 | B14: G02 | C14: IEMOCAP | D14: GCNet+AMBER | E14: (0.3,0.7,0.5) | F14: seed4 | G14: 59.950709 | H14: 59.735602 | I14: 61 | J14: Yes | K14: Match | L14: 3221226505
A15: G02-seed5 | B15: G02 | C15: IEMOCAP | D15: GCNet+AMBER | E15: (0.3,0.7,0.5) | F15: seed5 | G15: 60.443623 | H15: 58.843643 | I15: 126 | J15: Yes | K15: Match | L15: 3221226505
A16: G03-seed1 | B16: G03 | C16: IEMOCAP | D16: GCNet+AMBER | E16: (0.5,0.3,0.7) | F16: seed1 | G16: 65.372766 | H16: 65.125792 | I16: 133 | J16: Yes | K16: Match | L16: 3221226505
A17: G03-seed2 | B17: G03 | C17: IEMOCAP | D17: GCNet+AMBER | E17: (0.5,0.3,0.7) | F17: seed2 | G17: 63.401109 | H17: 62.240177 | I17: 137 | J17: Yes | K17: Match | L17: 3221226505
... A185: G36-seed5 | B185: G36 | C185: CMU-MOSEI | D185: MM-DFN+AMBER | E185: (0.7,0.5,0.3) | F185: seed5 | G185: 83.131535 | H185: 82.684837 | I185: 4 | J185: Yes | K185: Match | L185: 3221226505

Sheet Paper Values
A2: Values transcribed from the paper
A3: Baseline and BALM values are transcribed only. AMBER values link to run records through Group ID.
A5: Table | B5: Dataset | C5: Paper row | D5: IMR (A, L, V) | E5: Metric | F5: Reported value | G5: Reported SD | H5: Evidence scope | I5: Group ID
A6: 2 | B6: IEMOCAP | C6: MMIN | D6: (0.3,0.5,0.7) | E6: Acc | F6: 55.97 | H6: Transcribed; no run-level check
A7: 2 | B7: IEMOCAP | C7: MMIN | D7: (0.3,0.5,0.7) | E7: w-F1 | F7: 49.92 | H7: Transcribed; no run-level check
A8: 2 | B8: IEMOCAP | C8: MMIN | D8: (0.3,0.7,0.5) | E8: Acc | F8: 55.87 | H8: Transcribed; no run-level check
A9: 2 | B9: IEMOCAP | C9: MMIN | D9: (0.3,0.7,0.5) | E9: w-F1 | F9: 49.83 | H9: Transcribed; no run-level check
A10: 2 | B10: IEMOCAP | C10: MMIN | D10: (0.5,0.3,0.7) | E10: Acc | F10: 56.4 | H10: Transcribed; no run-level check
A11: 2 | B11: IEMOCAP | C11: MMIN | D11: (0.5,0.3,0.7) | E11: w-F1 | F11: 50.28 | H11: Transcribed; no run-level check
A12: 2 | B12: IEMOCAP | C12: MMIN | D12: (0.5,0.7,0.3) | E12: Acc | F12: 55.87 | H12: Transcribed; no run-level check
A13: 2 | B13: IEMOCAP | C13: MMIN | D13: (0.5,0.7,0.3) | E13: w-F1 | F13: 49.75 | H13: Transcribed; no run-level check
A14: 2 | B14: IEMOCAP | C14: MMIN | D14: (0.7,0.3,0.5) | E14: Acc | F14: 55.87 | H14: Transcribed; no run-level check
A15: 2 | B15: IEMOCAP | C15: MMIN | D15: (0.7,0.3,0.5) | E15: w-F1 | F15: 49.85 | H15: Transcribed; no run-level check
A16: 2 | B16: IEMOCAP | C16: MMIN | D16: (0.7,0.5,0.3) | E16: Acc | F16: 55.83 | H16: Transcribed; no run-level check
A17: 2 | B17: IEMOCAP | C17: MMIN | D17: (0.7,0.5,0.3) | E17: w-F1 | F17: 49.73 | H17: Transcribed; no run-level check
... A101: 2 | B101: IEMOCAP | C101: MCE | D101: (0.7,0.5,0.3) | E101: w-F1 | F101: 44.4 | H101: Transcribed; no run-level check
A102: 2 | B102: IEMOCAP | C102: GCNet+BALM | D102: (0.3,0.5,0.7) | E102: Acc | F102: 61.31 | G102: 0.75 | H102: Transcribed; no run-level check
A103: 2 | B103: IEMOCAP | C103: GCNet+BALM | D103: (0.3,0.5,0.7) | E103: w-F1 | F103: 61.33 | G103: 0.7 | H103: Transcribed; no run-level check
A104: 2 | B104: IEMOCAP | C104: GCNet+BALM | D104: (0.3,0.7,0.5) | E104: Acc | F104: 57.36 | G104: 0.76 | H104: Transcribed; no run-level check
A105: 2 | B105: IEMOCAP | C105: GCNet+BALM | D105: (0.3,0.7,0.5) | E105: w-F1 | F105: 57 | G105: 0.83 | H105: Transcribed; no run-level check
A106: 2 | B106: IEMOCAP | C106: GCNet+BALM | D106: (0.5,0.3,0.7) | E106: Acc | F106: 61.31 | G106: 0.63 | H106: Transcribed; no run-level check
A107: 2 | B107: IEMOCAP | C107: GCNet+BALM | D107: (0.5,0.3,0.7) | E107: w-F1 | F107: 61.62 | G107: 0.59 | H107: Transcribed; no run-level check
A108: 2 | B108: IEMOCAP | C108: GCNet+BALM | D108: (0.5,0.7,0.3) | E108: Acc | F108: 57.64 | G108: 1.1 | H108: Transcribed; no run-level check
A109: 2 | B109: IEMOCAP | C109: GCNet+BALM | D109: (0.5,0.7,0.3) | E109: w-F1 | F109: 57.64 | G109: 1.22 | H109: Transcribed; no run-level check
A110: 2 | B110: IEMOCAP | C110: GCNet+BALM | D110: (0.7,0.3,0.5) | E110: Acc | F110: 59.33 | G110: 0.46 | H110: Transcribed; no run-level check
A111: 2 | B111: IEMOCAP | C111: GCNet+BALM | D111: (0.7,0.3,0.5) | E111: w-F1 | F111: 59.39 | G111: 0.5 | H111: Transcribed; no run-level check
A112: 2 | B112: IEMOCAP | C112: GCNet+BALM | D112: (0.7,0.5,0.3) | E112: Acc | F112: 60.26 | G112: 0.83 | H112: Transcribed; no run-level check
A113: 2 | B113: IEMOCAP | C113: GCNet+BALM | D113: (0.7,0.5,0.3) | E113: w-F1 | F113: 60.58 | G113: 0.96 | H113: Transcribed; no run-level check
A114: 2 | B114: IEMOCAP | C114: GCNet+AMBER | D114: (0.3,0.5,0.7) | E114: Acc | F114: 61.85 | G114: 1.03 | H114: Linked to run records and logs | I114: G01
A115: 2 | B115: IEMOCAP | C115: GCNet+AMBER | D115: (0.3,0.5,0.7) | E115: w-F1 | F115: 61.68 | G115: 1.08 | H115: Linked to run records and logs | I115: G01
A116: 2 | B116: IEMOCAP | C116: GCNet+AMBER | D116: (0.3,0.7,0.5) | E116: Acc | F116: 59.93 | G116: 0.69 | H116: Linked to run records and logs | I116: G02
A117: 2 | B117: IEMOCAP | C117: GCNet+AMBER | D117: (0.3,0.7,0.5) | E117: w-F1 | F117: 59.2 | G117: 0.5 | H117: Linked to run records and logs | I117: G02
A118: 2 | B118: IEMOCAP | C118: GCNet+AMBER | D118: (0.5,0.3,0.7) | E118: Acc | F118: 65.16 | G118: 1.46 | H118: Linked to run records and logs | I118: G03
A119: 2 | B119: IEMOCAP | C119: GCNet+AMBER | D119: (0.5,0.3,0.7) | E119: w-F1 | F119: 64.68 | G119: 1.67 | H119: Linked to run records and logs | I119: G03
A120: 2 | B120: IEMOCAP | C120: GCNet+AMBER | D120: (0.5,0.7,0.3) | E120: Acc | F120: 60.58 | G120: 0.95 | H120: Linked to run records and logs | I120: G04
A121: 2 | B121: IEMOCAP | C121: GCNet+AMBER | D121: (0.5,0.7,0.3) | E121: w-F1 | F121: 60.22 | G121: 0.92 | H121: Linked to run records and logs | I121: G04
A122: 2 | B122: IEMOCAP | C122: GCNet+AMBER | D122: (0.7,0.3,0.5) | E122: Acc | F122: 65.35 | G122: 0.92 | H122: Linked to run records and logs | I122: G05
A123: 2 | B123: IEMOCAP | C123: GCNet+AMBER | D123: (0.7,0.3,0.5) | E123: w-F1 | F123: 64.9 | G123: 0.81 | H123: Linked to run records and logs | I123: G05
A124: 2 | B124: IEMOCAP | C124: GCNet+AMBER | D124: (0.7,0.5,0.3) | E124: Acc | F124: 62.38 | G124: 0.48 | H124: Linked to run records and logs | I124: G06
A125: 2 | B125: IEMOCAP | C125: GCNet+AMBER | D125: (0.7,0.5,0.3) | E125: w-F1 | F125: 61.87 | G125: 0.35 | H125: Linked to run records and logs | I125: G06
...

Sheet Cell Trace
A2: AMBER cells linked to run records
A3: Each mean or SD links to five unique run IDs. See metric_excerpts.jsonl for source excerpts.
A5: Cell ID | B5: Group ID | C5: Metric | D5: Statistic | E5: Reported value | F5: Recomputed (full) | G5: Recomputed (2dp) | H5: Match at 2dp | I5: Linked run IDs
A6: T2-G01-acc-mean | B6: G01 | C6: Acc | D6: mean | E6: 61.85 | F6: 61.848429 | G6: 61.85 | H6: Match | I6: G01-seed1;G01-seed2;G01-seed3;G01-seed4;G01-seed5
A7: T2-G01-acc-std | B7: G01 | C7: Acc | D7: std | E7: 1.03 | F7: 1.0322923 | G7: 1.03 | H7: Match | I7: G01-seed1;G01-seed2;G01-seed3;G01-seed4;G01-seed5
A8: T2-G01-wf1-mean | B8: G01 | C8: w-F1 | D8: mean | E8: 61.68 | F8: 61.684232 | G8: 61.68 | H8: Match | I8: G01-seed1;G01-seed2;G01-seed3;G01-seed4;G01-seed5
A9: T2-G01-wf1-std | B9: G01 | C9: w-F1 | D9: std | E9: 1.08 | F9: 1.0838387 | G9: 1.08 | H9: Match | I9: G01-seed1;G01-seed2;G01-seed3;G01-seed4;G01-seed5
A10: T2-G02-acc-mean | B10: G02 | C10: Acc | D10: mean | E10: 59.93 | F10: 59.926063 | G10: 59.93 | H10: Match | I10: G02-seed1;G02-seed2;G02-seed3;G02-seed4;G02-seed5
A11: T2-G02-acc-std | B11: G02 | C11: Acc | D11: std | E11: 0.69 | F11: 0.68831744 | G11: 0.69 | H11: Match | I11: G02-seed1;G02-seed2;G02-seed3;G02-seed4;G02-seed5
A12: T2-G02-wf1-mean | B12: G02 | C12: w-F1 | D12: mean | E12: 59.2 | F12: 59.200087 | G12: 59.2 | H12: Match | I12: G02-seed1;G02-seed2;G02-seed3;G02-seed4;G02-seed5
A13: T2-G02-wf1-std | B13: G02 | C13: w-F1 | D13: std | E13: 0.5 | F13: 0.49601531 | G13: 0.5 | H13: Match | I13: G02-seed1;G02-seed2;G02-seed3;G02-seed4;G02-seed5
A14: T2-G03-acc-mean | B14: G03 | C14: Acc | D14: mean | E14: 65.16 | F14: 65.163278 | G14: 65.16 | H14: Match | I14: G03-seed1;G03-seed2;G03-seed3;G03-seed4;G03-seed5
A15: T2-G03-acc-std | B15: G03 | C15: Acc | D15: std | E15: 1.46 | F15: 1.4610515 | G15: 1.46 | H15: Match | I15: G03-seed1;G03-seed2;G03-seed3;G03-seed4;G03-seed5
A16: T2-G03-wf1-mean | B16: G03 | C16: w-F1 | D16: mean | E16: 64.68 | F16: 64.681077 | G16: 64.68 | H16: Match | I16: G03-seed1;G03-seed2;G03-seed3;G03-seed4;G03-seed5
A17: T2-G03-wf1-std | B17: G03 | C17: w-F1 | D17: std | E17: 1.67 | F17: 1.6684784 | G17: 1.67 | H17: Match | I17: G03-seed1;G03-seed2;G03-seed3;G03-seed4;G03-seed5
... A149: T3-G36-wf1-std | B149: G36 | C149: w-F1 | D149: std | E149: 0.6 | F149: 0.59948527 | G149: 0.6 | H149: Match | I149: G36-seed1;G36-seed2;G36-seed3;G36-seed4;G36-seed5
